<?xml version='1.0'?>
<sdf version='1.6'>
  <model name='drone500'>
    <link name='body_1'>
      <pose frame=''>0 0 0 0 -0 0</pose>
      <inertial>
        <pose frame=''>0 0 0 0 -0 0</pose>
        <inertia>
          <ixx>1.8</ixx>
          <ixy>0</ixy>
          <ixz>0</ixz>
          <iyy>10.8</iyy>
          <iyz>0</iyz>
          <izz>10.8</izz>
        </inertia>
        <mass>10</mass>
      </inertial>
      <sensor name='imu_sensor' type='imu'>
        <always_on>1</always_on>
        <update_rate>1000</update_rate>
        <imu>
          <angular_velocity>
            <x>
              <noise type='gaussian'>
                <mean>0</mean>
                <stddev>0.0002</stddev>
                <bias_mean>7.5e-06</bias_mean>
                <bias_stddev>8e-07</bias_stddev>
              </noise>
            </x>
            <y>
              <noise type='gaussian'>
                <mean>0</mean>
                <stddev>0.0002</stddev>
                <bias_mean>7.5e-06</bias_mean>
                <bias_stddev>8e-07</bias_stddev>
              </noise>
            </y>
            <z>
              <noise type='gaussian'>
                <mean>0</mean>
                <stddev>0.0002</stddev>
                <bias_mean>7.5e-06</bias_mean>
                <bias_stddev>8e-07</bias_stddev>
              </noise>
            </z>
          </angular_velocity>
          <linear_acceleration>
            <x>
              <noise type='gaussian'>
                <mean>0</mean>
                <stddev>0.017</stddev>
                <bias_mean>0.1</bias_mean>
                <bias_stddev>0.001</bias_stddev>
              </noise>
            </x>
            <y>
              <noise type='gaussian'>
                <mean>0</mean>
                <stddev>0.017</stddev>
                <bias_mean>0.1</bias_mean>
                <bias_stddev>0.001</bias_stddev>
              </noise>
            </y>
            <z>
              <noise type='gaussian'>
                <mean>0</mean>
                <stddev>0.017</stddev>
                <bias_mean>0.1</bias_mean>
                <bias_stddev>0.001</bias_stddev>
              </noise>
            </z>
          </linear_acceleration>
        </imu>
        <pose frame=''>0 0 0 0 -0 0</pose>
      </sensor>
      <self_collide>0</self_collide>
      <enable_wind>0</enable_wind>
      <kinematic>0</kinematic>
      <gravity>1</gravity>
      <visual name='visual'>
        <geometry>

          <box>
            <size>3.6 0.2 0.2</size>
          </box>
        </geometry>
        <material>
          <ambient>0 0 0 1</ambient>
          <diffuse>0 0 0 1</diffuse>
          <script>
            <name>ModelPreview_12::body_1::visual_MATERIAL_</name>
            <uri>__default__</uri>
          </script>
          <shader type='vertex'>
            <normal_map>__default__</normal_map>
          </shader>
          <specular>0 0 0 1</specular>
          <emissive>0 0 0 1</emissive>
        </material>
        <pose frame=''>0 0 0 0 -0 0</pose>
        <transparency>0</transparency>
        <cast_shadows>1</cast_shadows>
      </visual>
      <collision name='collision'>
        <laser_retro>0</laser_retro>
        <max_contacts>10</max_contacts>
        <pose frame=''>0 0 0 0 -0 0</pose>
        <geometry>
          <box>
            <size>3.6 0.2 0.2</size>
          </box>
        </geometry>
        <surface>
          <friction>
            <ode>
              <mu>0.1</mu>
              <mu2>0.1</mu2>
              <fdir1>0 0 0</fdir1>
              <slip1>0</slip1>
              <slip2>0</slip2>
            </ode>
            <torsional>
              <coefficient>1</coefficient>
              <patch_radius>0</patch_radius>
              <surface_radius>0</surface_radius>
              <use_patch_radius>1</use_patch_radius>
              <ode>
                <slip>0</slip>
              </ode>
            </torsional>
          </friction>
          <bounce>
            <restitution_coefficient>0</restitution_coefficient>
            <threshold>1e+06</threshold>
          </bounce>
          <contact>
            <collide_without_contact>0</collide_without_contact>
            <collide_without_contact_bitmask>1</collide_without_contact_bitmask>
            <collide_bitmask>1</collide_bitmask>
            <ode>
              <soft_cfm>0</soft_cfm>
              <soft_erp>0.2</soft_erp>
              <kp>1e+13</kp>
              <kd>1</kd>
              <max_vel>0.01</max_vel>
              <min_depth>0</min_depth>
            </ode>
            <bullet>
              <split_impulse>1</split_impulse>
              <split_impulse_penetration_threshold>-0.01</split_impulse_penetration_threshold>
              <soft_cfm>0</soft_cfm>
              <soft_erp>0.2</soft_erp>
              <kp>1e+13</kp>
              <kd>1</kd>
            </bullet>
          </contact>
        </surface>
      </collision>
    </link>
    <link name='blade_1'>
      <pose frame=''>-1.75 0 0.18 0 -0 0</pose>
      <inertial>
        <pose frame=''>0 0.25 0 0 -0 0</pose>
        <inertia>
          <ixx>4.65e-05</ixx>
          <ixy>0</ixy>
          <ixz>0</ixz>
          <iyy>6e-07</iyy>
          <iyz>0</iyz>
          <izz>4.7e-05</izz>
        </inertia>
        <mass>0.01</mass>
      </inertial>
      <self_collide>0</self_collide>
      <enable_wind>0</enable_wind>
      <kinematic>0</kinematic>
      <gravity>1</gravity>
      <visual name='visual'>
        <pose frame=''>0 0.5 0 0 -0 0</pose>
        <geometry>
          <box>
            <size>0.2 1 0.01</size>
          </box>
        </geometry>
        <material>
          <ambient>0.667 0 0 1</ambient>
          <diffuse>0.667 0 0 1</diffuse>
          <script>
            <name>ModelPreview_12::blade_1::visual_MATERIAL_</name>
            <uri>__default__</uri>
          </script>
          <shader type='vertex'>
            <normal_map>__default__</normal_map>
          </shader>
          <specular>0.667 0 0 1</specular>
          <emissive>0 0 0 1</emissive>
        </material>
        <transparency>0</transparency>
        <cast_shadows>1</cast_shadows>
      </visual>
      <collision name='collision'>
        <laser_retro>0</laser_retro>
        <max_contacts>10</max_contacts>
        <pose frame=''>0 0.5 0 0 -0 0</pose>
        <geometry>
          <box>
            <size>0.2 1 0.01</size>
          </box>
        </geometry>
        <surface>
          <friction>
            <ode>
              <mu>1</mu>
              <mu2>1</mu2>
              <fdir1>0 0 0</fdir1>
              <slip1>0</slip1>
              <slip2>0</slip2>
            </ode>
            <torsional>
              <coefficient>1</coefficient>
              <patch_radius>0</patch_radius>
              <surface_radius>0</surface_radius>
              <use_patch_radius>1</use_patch_radius>
              <ode>
                <slip>0</slip>
              </ode>
            </torsional>
          </friction>
          <bounce>
            <restitution_coefficient>0</restitution_coefficient>
            <threshold>1e+06</threshold>
          </bounce>
          <contact>
            <collide_without_contact>0</collide_without_contact>
            <collide_without_contact_bitmask>1</collide_without_contact_bitmask>
            <collide_bitmask>1</collide_bitmask>
            <ode>
              <soft_cfm>0</soft_cfm>
              <soft_erp>0.2</soft_erp>
              <kp>1e+13</kp>
              <kd>1</kd>
              <max_vel>0.01</max_vel>
              <min_depth>0</min_depth>
            </ode>
            <bullet>
              <split_impulse>1</split_impulse>
              <split_impulse_penetration_threshold>-0.01</split_impulse_penetration_threshold>
              <soft_cfm>0</soft_cfm>
              <soft_erp>0.2</soft_erp>
              <kp>1e+13</kp>
              <kd>1</kd>
            </bullet>
          </contact>
        </surface>
      </collision>
    </link>
    <link name='blade_2'>
      <pose frame=''>-1.75 0 0.18 0 0 -3.14159</pose>
      <inertial>
        <pose frame=''>0 0.25 0 0 -0 0</pose>
        <inertia>
          <ixx>4.65e-05</ixx>
          <ixy>0</ixy>
          <ixz>0</ixz>
          <iyy>6e-07</iyy>
          <iyz>0</iyz>
          <izz>4.7e-05</izz>
        </inertia>
        <mass>0.01</mass>
      </inertial>
      <self_collide>0</self_collide>
      <enable_wind>0</enable_wind>
      <kinematic>0</kinematic>
      <gravity>1</gravity>
      <visual name='visual'>
        <pose frame=''>0 0.5 0 0 -0 0</pose>
        <geometry>
          <box>
            <size>0.2 1 0.01</size>
          </box>
        </geometry>
        <material>
          <ambient>0.667 0 0 1</ambient>
          <diffuse>0.667 0 0 1</diffuse>
          <script>
            <name>ModelPreview_12::blade_2::visual_MATERIAL_</name>
            <uri>__default__</uri>
          </script>
          <shader type='vertex'>
            <normal_map>__default__</normal_map>
          </shader>
          <specular>0.667 0 0 1</specular>
          <emissive>0 0 0 1</emissive>
        </material>
        <transparency>0</transparency>
        <cast_shadows>1</cast_shadows>
      </visual>
      <collision name='collision'>
        <laser_retro>0</laser_retro>
        <max_contacts>10</max_contacts>
        <pose frame=''>0 0.5 0 0 -0 0</pose>
        <geometry>
          <box>
            <size>0.2 1 0.01</size>
          </box>
        </geometry>
        <surface>
          <friction>
            <ode>
              <mu>1</mu>
              <mu2>1</mu2>
              <fdir1>0 0 0</fdir1>
              <slip1>0</slip1>
              <slip2>0</slip2>
            </ode>
            <torsional>
              <coefficient>1</coefficient>
              <patch_radius>0</patch_radius>
              <surface_radius>0</surface_radius>
              <use_patch_radius>1</use_patch_radius>
              <ode>
                <slip>0</slip>
              </ode>
            </torsional>
          </friction>
          <bounce>
            <restitution_coefficient>0</restitution_coefficient>
            <threshold>1e+06</threshold>
          </bounce>
          <contact>
            <collide_without_contact>0</collide_without_contact>
            <collide_without_contact_bitmask>1</collide_without_contact_bitmask>
            <collide_bitmask>1</collide_bitmask>
            <ode>
              <soft_cfm>0</soft_cfm>
              <soft_erp>0.2</soft_erp>
              <kp>1e+13</kp>
              <kd>1</kd>
              <max_vel>0.01</max_vel>
              <min_depth>0</min_depth>
            </ode>
            <bullet>
              <split_impulse>1</split_impulse>
              <split_impulse_penetration_threshold>-0.01</split_impulse_penetration_threshold>
              <soft_cfm>0</soft_cfm>
              <soft_erp>0.2</soft_erp>
              <kp>1e+13</kp>
              <kd>1</kd>
            </bullet>
          </contact>
        </surface>
      </collision>
    </link>
    <link name='blade_3'>
      <pose frame=''>1.75 0 0.18 0 -0 0</pose>
      <inertial>
        <pose frame=''>0 0.25 0 0 -0 0</pose>
        <inertia>
          <ixx>4.65e-05</ixx>
          <ixy>0</ixy>
          <ixz>0</ixz>
          <iyy>6e-07</iyy>
          <iyz>0</iyz>
          <izz>4.7e-05</izz>
        </inertia>
        <mass>0.01</mass>
      </inertial>
      <self_collide>0</self_collide>
      <enable_wind>0</enable_wind>
      <kinematic>0</kinematic>
      <gravity>1</gravity>
      <visual name='visual'>
        <pose frame=''>0 0.5 0 0 -0 0</pose>
        <geometry>
          <box>
            <size>0.2 1 0.01</size>
          </box>
        </geometry>
        <material>
          <ambient>0.667 0 0 1</ambient>
          <diffuse>0.667 0 0 1</diffuse>
          <script>
            <name>ModelPreview_12::blade_3::visual_MATERIAL_</name>
            <uri>__default__</uri>
          </script>
          <shader type='vertex'>
            <normal_map>__default__</normal_map>
          </shader>
          <specular>0.667 0 0 1</specular>
          <emissive>0 0 0 1</emissive>
        </material>
        <transparency>0</transparency>
        <cast_shadows>1</cast_shadows>
      </visual>
      <collision name='collision'>
        <laser_retro>0</laser_retro>
        <max_contacts>10</max_contacts>
        <pose frame=''>0 0.5 0 0 -0 0</pose>
        <geometry>
          <box>
            <size>0.2 1 0.01</size>
          </box>
        </geometry>
        <surface>
          <friction>
            <ode>
              <mu>1</mu>
              <mu2>1</mu2>
              <fdir1>0 0 0</fdir1>
              <slip1>0</slip1>
              <slip2>0</slip2>
            </ode>
            <torsional>
              <coefficient>1</coefficient>
              <patch_radius>0</patch_radius>
              <surface_radius>0</surface_radius>
              <use_patch_radius>1</use_patch_radius>
              <ode>
                <slip>0</slip>
              </ode>
            </torsional>
          </friction>
          <bounce>
            <restitution_coefficient>0</restitution_coefficient>
            <threshold>1e+06</threshold>
          </bounce>
          <contact>
            <collide_without_contact>0</collide_without_contact>
            <collide_without_contact_bitmask>1</collide_without_contact_bitmask>
            <collide_bitmask>1</collide_bitmask>
            <ode>
              <soft_cfm>0</soft_cfm>
              <soft_erp>0.2</soft_erp>
              <kp>1e+13</kp>
              <kd>1</kd>
              <max_vel>0.01</max_vel>
              <min_depth>0</min_depth>
            </ode>
            <bullet>
              <split_impulse>1</split_impulse>
              <split_impulse_penetration_threshold>-0.01</split_impulse_penetration_threshold>
              <soft_cfm>0</soft_cfm>
              <soft_erp>0.2</soft_erp>
              <kp>1e+13</kp>
              <kd>1</kd>
            </bullet>
          </contact>
        </surface>
      </collision>
    </link>
    <link name='blade_4'>
      <pose frame=''>1.75 0 0.18 0 0 -3.14159</pose>
      <inertial>
        <pose frame=''>0 0.25 0 0 -0 0</pose>
        <inertia>
          <ixx>4.65e-05</ixx>
          <ixy>0</ixy>
          <ixz>0</ixz>
          <iyy>6e-07</iyy>
          <iyz>0</iyz>
          <izz>4.7e-05</izz>
        </inertia>
        <mass>0.01</mass>
      </inertial>
      <self_collide>0</self_collide>
      <enable_wind>0</enable_wind>
      <kinematic>0</kinematic>
      <gravity>1</gravity>
      <visual name='visual'>
        <pose frame=''>0 0.5 0 0 -0 0</pose>
        <geometry>
          <box>
            <size>0.2 1 0.01</size>
          </box>
        </geometry>
        <material>
          <ambient>0.667 0 0 1</ambient>
          <diffuse>0.667 0 0 1</diffuse>
          <script>
            <name>ModelPreview_12::blade_4::visual_MATERIAL_</name>
            <uri>__default__</uri>
          </script>
          <shader type='vertex'>
            <normal_map>__default__</normal_map>
          </shader>
          <specular>0.667 0 0 1</specular>
          <emissive>0 0 0 1</emissive>
        </material>
        <transparency>0</transparency>
        <cast_shadows>1</cast_shadows>
      </visual>
      <collision name='collision'>
        <laser_retro>0</laser_retro>
        <max_contacts>10</max_contacts>
        <pose frame=''>0 0.5 0 0 -0 0</pose>
        <geometry>
          <box>
            <size>0.2 1 0.01</size>
          </box>
        </geometry>
        <surface>
          <friction>
            <ode>
              <mu>1</mu>
              <mu2>1</mu2>
              <fdir1>0 0 0</fdir1>
              <slip1>0</slip1>
              <slip2>0</slip2>
            </ode>
            <torsional>
              <coefficient>1</coefficient>
              <patch_radius>0</patch_radius>
              <surface_radius>0</surface_radius>
              <use_patch_radius>1</use_patch_radius>
              <ode>
                <slip>0</slip>
              </ode>
            </torsional>
          </friction>
          <bounce>
            <restitution_coefficient>0</restitution_coefficient>
            <threshold>1e+06</threshold>
          </bounce>
          <contact>
            <collide_without_contact>0</collide_without_contact>
            <collide_without_contact_bitmask>1</collide_without_contact_bitmask>
            <collide_bitmask>1</collide_bitmask>
            <ode>
              <soft_cfm>0</soft_cfm>
              <soft_erp>0.2</soft_erp>
              <kp>1e+13</kp>
              <kd>1</kd>
              <max_vel>0.01</max_vel>
              <min_depth>0</min_depth>
            </ode>
            <bullet>
              <split_impulse>1</split_impulse>
              <split_impulse_penetration_threshold>-0.01</split_impulse_penetration_threshold>
              <soft_cfm>0</soft_cfm>
              <soft_erp>0.2</soft_erp>
              <kp>1e+13</kp>
              <kd>1</kd>
            </bullet>
          </contact>
        </surface>
      </collision>
    </link>
    <link name='blade_5'>
      <pose frame=''>0 -1.75 0.18 0 -0 0</pose>
      <inertial>
        <pose frame=''>0 0.25 0 0 -0 0</pose>
        <inertia>
          <ixx>4.65e-05</ixx>
          <ixy>0</ixy>
          <ixz>0</ixz>
          <iyy>6e-07</iyy>
          <iyz>0</iyz>
          <izz>4.7e-05</izz>
        </inertia>
        <mass>0.01</mass>
      </inertial>
      <self_collide>0</self_collide>
      <enable_wind>0</enable_wind>
      <kinematic>0</kinematic>
      <gravity>1</gravity>
      <visual name='visual'>
        <pose frame=''>0 0.5 0 0 -0 0</pose>
        <geometry>
          <box>
            <size>0.2 1 0.01</size>
          </box>
        </geometry>
        <material>
          <ambient>0.667 0 0 1</ambient>
          <diffuse>0.667 0 0 1</diffuse>
          <script>
            <name>ModelPreview_12::blade_5::visual_MATERIAL_</name>
            <uri>__default__</uri>
          </script>
          <shader type='vertex'>
            <normal_map>__default__</normal_map>
          </shader>
          <specular>0.667 0 0 1</specular>
          <emissive>0.667 0 0 1</emissive>
        </material>
        <transparency>0</transparency>
        <cast_shadows>1</cast_shadows>
      </visual>
      <collision name='collision'>
        <laser_retro>0</laser_retro>
        <max_contacts>10</max_contacts>
        <pose frame=''>0 0.5 0 0 -0 0</pose>
        <geometry>
          <box>
            <size>0.2 1 0.01</size>
          </box>
        </geometry>
        <surface>
          <friction>
            <ode>
              <mu>1</mu>
              <mu2>1</mu2>
              <fdir1>0 0 0</fdir1>
              <slip1>0</slip1>
              <slip2>0</slip2>
            </ode>
            <torsional>
              <coefficient>1</coefficient>
              <patch_radius>0</patch_radius>
              <surface_radius>0</surface_radius>
              <use_patch_radius>1</use_patch_radius>
              <ode>
                <slip>0</slip>
              </ode>
            </torsional>
          </friction>
          <bounce>
            <restitution_coefficient>0</restitution_coefficient>
            <threshold>1e+06</threshold>
          </bounce>
          <contact>
            <collide_without_contact>0</collide_without_contact>
            <collide_without_contact_bitmask>1</collide_without_contact_bitmask>
            <collide_bitmask>1</collide_bitmask>
            <ode>
              <soft_cfm>0</soft_cfm>
              <soft_erp>0.2</soft_erp>
              <kp>1e+13</kp>
              <kd>1</kd>
              <max_vel>0.01</max_vel>
              <min_depth>0</min_depth>
            </ode>
            <bullet>
              <split_impulse>1</split_impulse>
              <split_impulse_penetration_threshold>-0.01</split_impulse_penetration_threshold>
              <soft_cfm>0</soft_cfm>
              <soft_erp>0.2</soft_erp>
              <kp>1e+13</kp>
              <kd>1</kd>
            </bullet>
          </contact>
        </surface>
      </collision>
    </link>
    <link name='blade_6'>
      <pose frame=''>0 -1.75 0.18 0 0 -3.14159</pose>
      <inertial>
        <pose frame=''>0 0.25 0 0 -0 0</pose>
        <inertia>
          <ixx>4.65e-05</ixx>
          <ixy>0</ixy>
          <ixz>0</ixz>
          <iyy>6e-07</iyy>
          <iyz>0</iyz>
          <izz>4.7e-05</izz>
        </inertia>
        <mass>0.01</mass>
      </inertial>
      <self_collide>0</self_collide>
      <enable_wind>0</enable_wind>
      <kinematic>0</kinematic>
      <gravity>1</gravity>
      <visual name='visual'>
        <pose frame=''>0 0.5 0 0 -0 0</pose>
        <geometry>
          <box>
            <size>0.2 1 0.01</size>
          </box>
        </geometry>
        <material>
          <ambient>0.667 0 0 1</ambient>
          <diffuse>0.667 0 0 1</diffuse>
          <script>
            <name>ModelPreview_12::blade_6::visual_MATERIAL_</name>
            <uri>__default__</uri>
          </script>
          <shader type='vertex'>
            <normal_map>__default__</normal_map>
          </shader>
          <specular>0.667 0 0 1</specular>
          <emissive>0.667 0 0 1</emissive>
        </material>
        <transparency>0</transparency>
        <cast_shadows>1</cast_shadows>
      </visual>
      <collision name='collision'>
        <laser_retro>0</laser_retro>
        <max_contacts>10</max_contacts>
        <pose frame=''>0 0.5 0 0 -0 0</pose>
        <geometry>
          <box>
            <size>0.2 1 0.01</size>
          </box>
        </geometry>
        <surface>
          <friction>
            <ode>
              <mu>1</mu>
              <mu2>1</mu2>
              <fdir1>0 0 0</fdir1>
              <slip1>0</slip1>
              <slip2>0</slip2>
            </ode>
            <torsional>
              <coefficient>1</coefficient>
              <patch_radius>0</patch_radius>
              <surface_radius>0</surface_radius>
              <use_patch_radius>1</use_patch_radius>
              <ode>
                <slip>0</slip>
              </ode>
            </torsional>
          </friction>
          <bounce>
            <restitution_coefficient>0</restitution_coefficient>
            <threshold>1e+06</threshold>
          </bounce>
          <contact>
            <collide_without_contact>0</collide_without_contact>
            <collide_without_contact_bitmask>1</collide_without_contact_bitmask>
            <collide_bitmask>1</collide_bitmask>
            <ode>
              <soft_cfm>0</soft_cfm>
              <soft_erp>0.2</soft_erp>
              <kp>1e+13</kp>
              <kd>1</kd>
              <max_vel>0.01</max_vel>
              <min_depth>0</min_depth>
            </ode>
            <bullet>
              <split_impulse>1</split_impulse>
              <split_impulse_penetration_threshold>-0.01</split_impulse_penetration_threshold>
              <soft_cfm>0</soft_cfm>
              <soft_erp>0.2</soft_erp>
              <kp>1e+13</kp>
              <kd>1</kd>
            </bullet>
          </contact>
        </surface>
      </collision>
    </link>
    <link name='blade_7'>
      <pose frame=''>0 1.75 0.18 0 -0 0</pose>
      <inertial>
        <pose frame=''>0 0.25 0 0 -0 0</pose>
        <inertia>
          <ixx>4.65e-05</ixx>
          <ixy>0</ixy>
          <ixz>0</ixz>
          <iyy>6e-07</iyy>
          <iyz>0</iyz>
          <izz>4.7e-05</izz>
        </inertia>
        <mass>0.01</mass>
      </inertial>
      <self_collide>0</self_collide>
      <enable_wind>0</enable_wind>
      <kinematic>0</kinematic>
      <gravity>1</gravity>
      <visual name='visual'>
        <pose frame=''>0 0.5 0 0 -0 0</pose>
        <geometry>
          <box>
            <size>0.2 1 0.01</size>
          </box>
        </geometry>
        <material>
          <ambient>0.667 0 0 1</ambient>
          <diffuse>0.667 0 0 1</diffuse>
          <script>
            <name>ModelPreview_12::blade_7::visual_MATERIAL_</name>
            <uri>__default__</uri>
          </script>
          <shader type='vertex'>
            <normal_map>__default__</normal_map>
          </shader>
          <specular>0.667 0 0 1</specular>
          <emissive>0.667 0 0 1</emissive>
        </material>
        <transparency>0</transparency>
        <cast_shadows>1</cast_shadows>
      </visual>
      <collision name='collision'>
        <laser_retro>0</laser_retro>
        <max_contacts>10</max_contacts>
        <pose frame=''>0 0.5 0 0 -0 0</pose>
        <geometry>
          <box>
            <size>0.2 1 0.01</size>
          </box>
        </geometry>
        <surface>
          <friction>
            <ode>
              <mu>1</mu>
              <mu2>1</mu2>
              <fdir1>0 0 0</fdir1>
              <slip1>0</slip1>
              <slip2>0</slip2>
            </ode>
            <torsional>
              <coefficient>1</coefficient>
              <patch_radius>0</patch_radius>
              <surface_radius>0</surface_radius>
              <use_patch_radius>1</use_patch_radius>
              <ode>
                <slip>0</slip>
              </ode>
            </torsional>
          </friction>
          <bounce>
            <restitution_coefficient>0</restitution_coefficient>
            <threshold>1e+06</threshold>
          </bounce>
          <contact>
            <collide_without_contact>0</collide_without_contact>
            <collide_without_contact_bitmask>1</collide_without_contact_bitmask>
            <collide_bitmask>1</collide_bitmask>
            <ode>
              <soft_cfm>0</soft_cfm>
              <soft_erp>0.2</soft_erp>
              <kp>1e+13</kp>
              <kd>1</kd>
              <max_vel>0.01</max_vel>
              <min_depth>0</min_depth>
            </ode>
            <bullet>
              <split_impulse>1</split_impulse>
              <split_impulse_penetration_threshold>-0.01</split_impulse_penetration_threshold>
              <soft_cfm>0</soft_cfm>
              <soft_erp>0.2</soft_erp>
              <kp>1e+13</kp>
              <kd>1</kd>
            </bullet>
          </contact>
        </surface>
      </collision>
    </link>
    <link name='blade_8'>
      <pose frame=''>0 1.75 0.18 0 0 -3.14159</pose>
      <inertial>
        <pose frame=''>0 0.25 0 0 -0 0</pose>
        <inertia>
          <ixx>4.65e-05</ixx>
          <ixy>0</ixy>
          <ixz>0</ixz>
          <iyy>6e-07</iyy>
          <iyz>0</iyz>
          <izz>4.7e-05</izz>
        </inertia>
        <mass>0.01</mass>
      </inertial>
      <self_collide>0</self_collide>
      <enable_wind>0</enable_wind>
      <kinematic>0</kinematic>
      <gravity>1</gravity>
      <visual name='visual'>
        <pose frame=''>0 0.5 0 0 -0 0</pose>
        <geometry>
          <box>
            <size>0.2 1 0.01</size>
          </box>
        </geometry>
        <material>
          <ambient>0.667 0 0 1</ambient>
          <diffuse>0.667 0 0 1</diffuse>
          <script>
            <name>ModelPreview_12::blade_8::visual_MATERIAL_</name>
            <uri>__default__</uri>
          </script>
          <shader type='vertex'>
            <normal_map>__default__</normal_map>
          </shader>
          <specular>0.667 0 0 1</specular>
          <emissive>0.667 0 0 1</emissive>
        </material>
        <transparency>0</transparency>
        <cast_shadows>1</cast_shadows>
      </visual>
      <collision name='collision'>
        <laser_retro>0</laser_retro>
        <max_contacts>10</max_contacts>
        <pose frame=''>0 0.5 0 0 -0 0</pose>
        <geometry>
          <box>
            <size>0.2 1 0.01</size>
          </box>
        </geometry>
        <surface>
          <friction>
            <ode>
              <mu>1</mu>
              <mu2>1</mu2>
              <fdir1>0 0 0</fdir1>
              <slip1>0</slip1>
              <slip2>0</slip2>
            </ode>
            <torsional>
              <coefficient>1</coefficient>
              <patch_radius>0</patch_radius>
              <surface_radius>0</surface_radius>
              <use_patch_radius>1</use_patch_radius>
              <ode>
                <slip>0</slip>
              </ode>
            </torsional>
          </friction>
          <bounce>
            <restitution_coefficient>0</restitution_coefficient>
            <threshold>1e+06</threshold>
          </bounce>
          <contact>
            <collide_without_contact>0</collide_without_contact>
            <collide_without_contact_bitmask>1</collide_without_contact_bitmask>
            <collide_bitmask>1</collide_bitmask>
            <ode>
              <soft_cfm>0</soft_cfm>
              <soft_erp>0.2</soft_erp>
              <kp>1e+13</kp>
              <kd>1</kd>
              <max_vel>0.01</max_vel>
              <min_depth>0</min_depth>
            </ode>
            <bullet>
              <split_impulse>1</split_impulse>
              <split_impulse_penetration_threshold>-0.01</split_impulse_penetration_threshold>
              <soft_cfm>0</soft_cfm>
              <soft_erp>0.2</soft_erp>
              <kp>1e+13</kp>
              <kd>1</kd>
            </bullet>
          </contact>
        </surface>
      </collision>
    </link>
    <link name='body_2'>
      <pose frame=''>0 0 0 0 -0 0</pose>
      <inertial>
        <pose frame=''>0 0 0 0 -0 0</pose>
        <inertia>
          <ixx>10.8</ixx>
          <ixy>0</ixy>
          <ixz>0</ixz>
          <iyy>1.8</iyy>
          <iyz>0</iyz>
          <izz>10.8</izz>
        </inertia>
        <mass>10</mass>
      </inertial>
      <self_collide>0</self_collide>
      <enable_wind>0</enable_wind>
      <kinematic>0</kinematic>
      <gravity>1</gravity>
      <visual name='visual'>
        <geometry>
          <box>
            <size>0.2 3.6 0.2</size>
          </box>
        </geometry>
        <material>
          <ambient>0 0 0 1</ambient>
          <diffuse>0 0 0 1</diffuse>
          <script>
            <name>ModelPreview_12::body_2::visual_MATERIAL_</name>
            <uri>__default__</uri>
          </script>
          <shader type='vertex'>
            <normal_map>__default__</normal_map>
          </shader>
          <specular>0 0 0 1</specular>
          <emissive>0 0 0 1</emissive>
        </material>
        <pose frame=''>0 0 0 0 -0 0</pose>
        <transparency>0</transparency>
        <cast_shadows>1</cast_shadows>
      </visual>
      <collision name='collision'>
        <laser_retro>0</laser_retro>
        <max_contacts>10</max_contacts>
        <pose frame=''>0 0 0 0 -0 0</pose>
        <geometry>
          <box>
            <size>0.2 3.6 0.2</size>
          </box>
        </geometry>
        <surface>
          <friction>
            <ode>
              <mu>0.1</mu>
              <mu2>0.1</mu2>
              <fdir1>0 0 0</fdir1>
              <slip1>0</slip1>
              <slip2>0</slip2>
            </ode>
            <torsional>
              <coefficient>1</coefficient>
              <patch_radius>0</patch_radius>
              <surface_radius>0</surface_radius>
              <use_patch_radius>1</use_patch_radius>
              <ode>
                <slip>0</slip>
              </ode>
            </torsional>
          </friction>
          <bounce>
            <restitution_coefficient>0</restitution_coefficient>
            <threshold>1e+06</threshold>
          </bounce>
          <contact>
            <collide_without_contact>0</collide_without_contact>
            <collide_without_contact_bitmask>1</collide_without_contact_bitmask>
            <collide_bitmask>1</collide_bitmask>
            <ode>
              <soft_cfm>0</soft_cfm>
              <soft_erp>0.2</soft_erp>
              <kp>1e+13</kp>
              <kd>1</kd>
              <max_vel>0.01</max_vel>
              <min_depth>0</min_depth>
            </ode>
            <bullet>
              <split_impulse>1</split_impulse>
              <split_impulse_penetration_threshold>-0.01</split_impulse_penetration_threshold>
              <soft_cfm>0</soft_cfm>
              <soft_erp>0.2</soft_erp>
              <kp>1e+13</kp>
              <kd>1</kd>
            </bullet>
          </contact>
        </surface>
      </collision>
    </link>
    <link name='rod_1'>
      <pose frame=''>-1.75 0 0.14 0 -0 0</pose>
      <inertial>
        <pose frame=''>0 0 0 0 -0 0</pose>
        <inertia>
          <ixx>0.012</ixx>
          <ixy>0</ixy>
          <ixz>0</ixz>
          <iyy>0.012</iyy>
          <iyz>0</iyz>
          <izz>0.0012</izz>
        </inertia>
        <mass>1</mass>
      </inertial>
      <self_collide>0</self_collide>
      <enable_wind>0</enable_wind>
      <kinematic>0</kinematic>
      <gravity>1</gravity>
      <visual name='visual'>
        <geometry>
          <box>
            <size>0.02 0.02 0.08</size>
          </box>
        </geometry>
        <material>
          <ambient>0.3 0.3 0.3 1</ambient>
          <diffuse>0.421 0.225 0 1</diffuse>
          <script>
            <name>ModelPreview_12::rod_1::visual_MATERIAL_</name>
            <uri>__default__</uri>
          </script>
          <shader type='vertex'>
            <normal_map>__default__</normal_map>
          </shader>
          <specular>0 0 0 1</specular>
          <emissive>0 0 0 1</emissive>
        </material>
        <pose frame=''>0 0 0 0 -0 0</pose>
        <transparency>0</transparency>
        <cast_shadows>1</cast_shadows>
      </visual>
      <collision name='collision'>
        <laser_retro>0</laser_retro>
        <max_contacts>10</max_contacts>
        <pose frame=''>0 0 0 0 -0 0</pose>
        <geometry>
          <box>
            <size>0.02 0.02 0.08</size>
          </box>
        </geometry>
        <surface>
          <friction>
            <ode>
              <mu>1</mu>
              <mu2>1</mu2>
              <fdir1>0 0 0</fdir1>
              <slip1>0</slip1>
              <slip2>0</slip2>
            </ode>
            <torsional>
              <coefficient>1</coefficient>
              <patch_radius>0</patch_radius>
              <surface_radius>0</surface_radius>
              <use_patch_radius>1</use_patch_radius>
              <ode>
                <slip>0</slip>
              </ode>
            </torsional>
          </friction>
          <bounce>
            <restitution_coefficient>0</restitution_coefficient>
            <threshold>1e+06</threshold>
          </bounce>
          <contact>
            <collide_without_contact>0</collide_without_contact>
            <collide_without_contact_bitmask>1</collide_without_contact_bitmask>
            <collide_bitmask>1</collide_bitmask>
            <ode>
              <soft_cfm>0</soft_cfm>
              <soft_erp>0.2</soft_erp>
              <kp>1e+13</kp>
              <kd>1</kd>
              <max_vel>0.01</max_vel>
              <min_depth>0</min_depth>
            </ode>
            <bullet>
              <split_impulse>1</split_impulse>
              <split_impulse_penetration_threshold>-0.01</split_impulse_penetration_threshold>
              <soft_cfm>0</soft_cfm>
              <soft_erp>0.2</soft_erp>
              <kp>1e+13</kp>
              <kd>1</kd>
            </bullet>
          </contact>
        </surface>
      </collision>
    </link>
    <link name='rod_2'>
      <pose frame=''>1.75 0 0.14 0 -0 0</pose>
      <inertial>
        <pose frame=''>0 0 0 0 -0 0</pose>
        <inertia>
          <ixx>0.012</ixx>
          <ixy>0</ixy>
          <ixz>0</ixz>
          <iyy>0.012</iyy>
          <iyz>0</iyz>
          <izz>0.0012</izz>
        </inertia>
        <mass>1</mass>
      </inertial>
      <self_collide>0</self_collide>
      <enable_wind>0</enable_wind>
      <kinematic>0</kinematic>
      <visual name='visual'>
        <geometry>
          <box>
            <size>0.02 0.02 0.08</size>
          </box>
        </geometry>
        <material>
          <ambient>0.3 0.3 0.3 1</ambient>
          <diffuse>0.421 0.225 0 1</diffuse>
          <script>
            <name>ModelPreview_12::rod_2::visual_MATERIAL_</name>
            <uri>__default__</uri>
          </script>
        </material>
        <pose frame=''>0 0 0 0 -0 0</pose>
        <transparency>0</transparency>
        <cast_shadows>1</cast_shadows>
      </visual>
      <collision name='collision'>
        <laser_retro>0</laser_retro>
        <max_contacts>10</max_contacts>
        <pose frame=''>0 0 0 0 -0 0</pose>
        <geometry>
          <box>
            <size>0.02 0.02 0.08</size>
          </box>
        </geometry>
        <surface>
          <friction>
            <ode>
              <mu>1</mu>
              <mu2>1</mu2>
              <fdir1>0 0 0</fdir1>
              <slip1>0</slip1>
              <slip2>0</slip2>
            </ode>
            <torsional>
              <coefficient>1</coefficient>
              <patch_radius>0</patch_radius>
              <surface_radius>0</surface_radius>
              <use_patch_radius>1</use_patch_radius>
              <ode>
                <slip>0</slip>
              </ode>
            </torsional>
          </friction>
          <bounce>
            <restitution_coefficient>0</restitution_coefficient>
            <threshold>1e+06</threshold>
          </bounce>
          <contact>
            <collide_without_contact>0</collide_without_contact>
            <collide_without_contact_bitmask>1</collide_without_contact_bitmask>
            <collide_bitmask>1</collide_bitmask>
            <ode>
              <soft_cfm>0</soft_cfm>
              <soft_erp>0.2</soft_erp>
              <kp>1e+13</kp>
              <kd>1</kd>
              <max_vel>0.01</max_vel>
              <min_depth>0</min_depth>
            </ode>
            <bullet>
              <split_impulse>1</split_impulse>
              <split_impulse_penetration_threshold>-0.01</split_impulse_penetration_threshold>
              <soft_cfm>0</soft_cfm>
              <soft_erp>0.2</soft_erp>
              <kp>1e+13</kp>
              <kd>1</kd>
            </bullet>
          </contact>
        </surface>
      </collision>
    </link>
    <link name='rod_3'>
      <pose frame=''>0 -1.75 0.14 0 -0 0</pose>
      <inertial>
        <pose frame=''>0 0 0 0 -0 0</pose>
        <inertia>
          <ixx>0.012</ixx>
          <ixy>0</ixy>
          <ixz>0</ixz>
          <iyy>0.012</iyy>
          <iyz>0</iyz>
          <izz>0.0012</izz>
        </inertia>
        <mass>1</mass>
      </inertial>
      <self_collide>0</self_collide>
      <enable_wind>0</enable_wind>
      <kinematic>0</kinematic>
      <visual name='visual'>
        <geometry>
          <box>
            <size>0.02 0.02 0.08</size>
          </box>
        </geometry>
        <material>
          <ambient>0.3 0.3 0.3 1</ambient>
          <diffuse>0.421 0.225 0 1</diffuse>
          <script>
            <name>ModelPreview_12::rod_3::visual_MATERIAL_</name>
            <uri>__default__</uri>
          </script>
        </material>
        <pose frame=''>0 0 0 0 -0 0</pose>
        <transparency>0</transparency>
        <cast_shadows>1</cast_shadows>
      </visual>
      <collision name='collision'>
        <laser_retro>0</laser_retro>
        <max_contacts>10</max_contacts>
        <pose frame=''>0 0 0 0 -0 0</pose>
        <geometry>
          <box>
            <size>0.02 0.02 0.08</size>
          </box>
        </geometry>
        <surface>
          <friction>
            <ode>
              <mu>1</mu>
              <mu2>1</mu2>
              <fdir1>0 0 0</fdir1>
              <slip1>0</slip1>
              <slip2>0</slip2>
            </ode>
            <torsional>
              <coefficient>1</coefficient>
              <patch_radius>0</patch_radius>
              <surface_radius>0</surface_radius>
              <use_patch_radius>1</use_patch_radius>
              <ode>
                <slip>0</slip>
              </ode>
            </torsional>
          </friction>
          <bounce>
            <restitution_coefficient>0</restitution_coefficient>
            <threshold>1e+06</threshold>
          </bounce>
          <contact>
            <collide_without_contact>0</collide_without_contact>
            <collide_without_contact_bitmask>1</collide_without_contact_bitmask>
            <collide_bitmask>1</collide_bitmask>
            <ode>
              <soft_cfm>0</soft_cfm>
              <soft_erp>0.2</soft_erp>
              <kp>1e+13</kp>
              <kd>1</kd>
              <max_vel>0.01</max_vel>
              <min_depth>0</min_depth>
            </ode>
            <bullet>
              <split_impulse>1</split_impulse>
              <split_impulse_penetration_threshold>-0.01</split_impulse_penetration_threshold>
              <soft_cfm>0</soft_cfm>
              <soft_erp>0.2</soft_erp>
              <kp>1e+13</kp>
              <kd>1</kd>
            </bullet>
          </contact>
        </surface>
      </collision>
    </link>
    <link name='rod_4'>
      <pose frame=''>0 1.75 0.14 0 -0 0</pose>
      <inertial>
        <pose frame=''>0 0 0 0 -0 0</pose>
        <inertia>
          <ixx>0.012</ixx>
          <ixy>0</ixy>
          <ixz>0</ixz>
          <iyy>0.012</iyy>
          <iyz>0</iyz>
          <izz>0.0012</izz>
        </inertia>
        <mass>1</mass>
      </inertial>
      <self_collide>0</self_collide>
      <enable_wind>0</enable_wind>
      <kinematic>0</kinematic>
      <visual name='visual'>
        <geometry>
          <box>
            <size>0.02 0.02 0.08</size>
          </box>
        </geometry>
        <material>
          <ambient>0.3 0.3 0.3 1</ambient>
          <diffuse>0.421 0.225 0 1</diffuse>
          <script>
            <name>ModelPreview_12::rod_4::visual_MATERIAL_</name>
            <uri>__default__</uri>
          </script>
        </material>
        <pose frame=''>0 0 0 0 -0 0</pose>
        <transparency>0</transparency>
        <cast_shadows>1</cast_shadows>
      </visual>
      <collision name='collision'>
        <laser_retro>0</laser_retro>
        <max_contacts>10</max_contacts>
        <pose frame=''>0 0 0 0 -0 0</pose>
        <geometry>
          <box>
            <size>0.02 0.02 0.08</size>
          </box>
        </geometry>
        <surface>
          <friction>
            <ode>
              <mu>1</mu>
              <mu2>1</mu2>
              <fdir1>0 0 0</fdir1>
              <slip1>0</slip1>
              <slip2>0</slip2>
            </ode>
            <torsional>
              <coefficient>1</coefficient>
              <patch_radius>0</patch_radius>
              <surface_radius>0</surface_radius>
              <use_patch_radius>1</use_patch_radius>
              <ode>
                <slip>0</slip>
              </ode>
            </torsional>
          </friction>
          <bounce>
            <restitution_coefficient>0</restitution_coefficient>
            <threshold>1e+06</threshold>
          </bounce>
          <contact>
            <collide_without_contact>0</collide_without_contact>
            <collide_without_contact_bitmask>1</collide_without_contact_bitmask>
            <collide_bitmask>1</collide_bitmask>
            <ode>
              <soft_cfm>0</soft_cfm>
              <soft_erp>0.2</soft_erp>
              <kp>1e+13</kp>
              <kd>1</kd>
              <max_vel>0.01</max_vel>
              <min_depth>0</min_depth>
            </ode>
            <bullet>
              <split_impulse>1</split_impulse>
              <split_impulse_penetration_threshold>-0.01</split_impulse_penetration_threshold>
              <soft_cfm>0</soft_cfm>
              <soft_erp>0.2</soft_erp>
              <kp>1e+13</kp>
              <kd>1</kd>
            </bullet>
          </contact>
        </surface>
      </collision>
    </link>
    <joint name='b1_joint' type='revolute'>
      <parent>rod_1</parent>
      <child>blade_1</child>
      <pose frame=''>0 0 0 0 -0 0</pose>
      <axis>
        <xyz>1 0 0</xyz>
        <use_parent_model_frame>0</use_parent_model_frame>
        <limit>
          <lower>0</lower>
          <upper>0</upper>
          <effort>-1</effort>
          <velocity>-1</velocity>
        </limit>
        <dynamics>
          <spring_reference>0</spring_reference>
          <spring_stiffness>0</spring_stiffness>
          <damping>1</damping>
          <friction>0</friction>
        </dynamics>
      </axis>
      <physics>
        <ode>
          <limit>
            <cfm>0</cfm>
            <erp>0.2</erp>
          </limit>
          <suspension>
            <cfm>0</cfm>
            <erp>0.2</erp>
          </suspension>
        </ode>
      </physics>
    </joint>
    <joint name='b2_joint' type='revolute'>
      <parent>rod_1</parent>
      <child>blade_2</child>
      <pose frame=''>0 0 0 0 -0 0</pose>
      <axis>
        <xyz>1 0 0</xyz>
        <use_parent_model_frame>0</use_parent_model_frame>
        <limit>
          <lower>0</lower>
          <upper>0</upper>
          <effort>-1</effort>
          <velocity>-1</velocity>
        </limit>
        <dynamics>
          <spring_reference>0</spring_reference>
          <spring_stiffness>0</spring_stiffness>
          <damping>1</damping>
          <friction>0</friction>
        </dynamics>
      </axis>
      <physics>
        <ode>
          <limit>
            <cfm>0</cfm>
            <erp>0.2</erp>
          </limit>
          <suspension>
            <cfm>0</cfm>
            <erp>0.2</erp>
          </suspension>
        </ode>
      </physics>
    </joint>
    <joint name='b3_joint' type='revolute'>
      <parent>rod_2</parent>
      <child>blade_3</child>
      <pose frame=''>0 0 0 0 -0 0</pose>
      <axis>
        <xyz>1 0 0</xyz>
        <use_parent_model_frame>0</use_parent_model_frame>
        <limit>
          <lower>0</lower>
          <upper>0</upper>
          <effort>-1</effort>
          <velocity>-1</velocity>
        </limit>
        <dynamics>
          <spring_reference>0</spring_reference>
          <spring_stiffness>0</spring_stiffness>
          <damping>1</damping>
          <friction>0</friction>
        </dynamics>
      </axis>
      <physics>
        <ode>
          <limit>
            <cfm>0</cfm>
            <erp>0.2</erp>
          </limit>
          <suspension>
            <cfm>0</cfm>
            <erp>0.2</erp>
          </suspension>
        </ode>
      </physics>
    </joint>
    <joint name='b4_joint' type='revolute'>
      <parent>rod_2</parent>
      <child>blade_4</child>
      <pose frame=''>0 0 0 0 -0 0</pose>
      <axis>
        <xyz>1 0 0</xyz>
        <use_parent_model_frame>0</use_parent_model_frame>
        <limit>
          <lower>0</lower>
          <upper>0</upper>
          <effort>-1</effort>
          <velocity>-1</velocity>
        </limit>
        <dynamics>
          <spring_reference>0</spring_reference>
          <spring_stiffness>0</spring_stiffness>
          <damping>1</damping>
          <friction>0</friction>
        </dynamics>
      </axis>
      <physics>
        <ode>
          <limit>
            <cfm>0</cfm>
            <erp>0.2</erp>
          </limit>
          <suspension>
            <cfm>0</cfm>
            <erp>0.2</erp>
          </suspension>
        </ode>
      </physics>
    </joint>
    <joint name='b5_joint' type='revolute'>
      <parent>rod_3</parent>
      <child>blade_5</child>
      <pose frame=''>0 0 0 0 -0 0</pose>
      <axis>
        <xyz>1 0 0</xyz>
        <use_parent_model_frame>0</use_parent_model_frame>
        <limit>
          <lower>0</lower>
          <upper>0</upper>
          <effort>-1</effort>
          <velocity>-1</velocity>
        </limit>
        <dynamics>
          <spring_reference>0</spring_reference>
          <spring_stiffness>0</spring_stiffness>
          <damping>1</damping>
          <friction>0</friction>
        </dynamics>
      </axis>
      <physics>
        <ode>
          <limit>
            <cfm>0</cfm>
            <erp>0.2</erp>
          </limit>
          <suspension>
            <cfm>0</cfm>
            <erp>0.2</erp>
          </suspension>
        </ode>
      </physics>
    </joint>
    <joint name='b6_joint' type='revolute'>
      <parent>rod_3</parent>
      <child>blade_6</child>
      <pose frame=''>0 0 0 0 -0 0</pose>
      <axis>
        <xyz>1 0 0</xyz>
        <use_parent_model_frame>0</use_parent_model_frame>
        <limit>
          <lower>0</lower>
          <upper>0</upper>
          <effort>-1</effort>
          <velocity>-1</velocity>
        </limit>
        <dynamics>
          <spring_reference>0</spring_reference>
          <spring_stiffness>0</spring_stiffness>
          <damping>1</damping>
          <friction>0</friction>
        </dynamics>
      </axis>
      <physics>
        <ode>
          <limit>
            <cfm>0</cfm>
            <erp>0.2</erp>
          </limit>
          <suspension>
            <cfm>0</cfm>
            <erp>0.2</erp>
          </suspension>
        </ode>
      </physics>
    </joint>
    <joint name='b7_joint' type='revolute'>
      <parent>rod_4</parent>
      <child>blade_7</child>
      <pose frame=''>0 0 0 0 -0 0</pose>
      <axis>
        <xyz>1 0 0</xyz>
        <use_parent_model_frame>0</use_parent_model_frame>
        <limit>
          <lower>0</lower>
          <upper>0</upper>
          <effort>-1</effort>
          <velocity>-1</velocity>
        </limit>
        <dynamics>
          <spring_reference>0</spring_reference>
          <spring_stiffness>0</spring_stiffness>
          <damping>1</damping>
          <friction>0</friction>
        </dynamics>
      </axis>
      <physics>
        <ode>
          <limit>
            <cfm>0</cfm>
            <erp>0.2</erp>
          </limit>
          <suspension>
            <cfm>0</cfm>
            <erp>0.2</erp>
          </suspension>
        </ode>
      </physics>
    </joint>
    <joint name='b8_joint' type='revolute'>
      <parent>rod_4</parent>
      <child>blade_8</child>
      <pose frame=''>0 0 0 0 -0 0</pose>
      <axis>
        <xyz>1 0 0</xyz>
        <use_parent_model_frame>0</use_parent_model_frame>
        <limit>
          <lower>0</lower>
          <upper>0</upper>
          <effort>-1</effort>
          <velocity>-1</velocity>
        </limit>
        <dynamics>
          <spring_reference>0</spring_reference>
          <spring_stiffness>0</spring_stiffness>
          <damping>1</damping>
          <friction>0</friction>
        </dynamics>
      </axis>
      <physics>
        <ode>
          <limit>
            <cfm>0</cfm>
            <erp>0.2</erp>
          </limit>
          <suspension>
            <cfm>0</cfm>
            <erp>0.2</erp>
          </suspension>
        </ode>
      </physics>
    </joint>
    <joint name='body_joint' type='revolute'>
      <parent>body_1</parent>
      <child>body_2</child>
      <pose frame=''>0 0 0 0 -0 0</pose>
      <axis>
        <xyz>0 0 1</xyz>
        <use_parent_model_frame>0</use_parent_model_frame>
        <limit>
          <lower>0</lower>
          <upper>0</upper>
          <effort>-1</effort>
          <velocity>-1</velocity>
        </limit>
        <dynamics>
          <spring_reference>0</spring_reference>
          <spring_stiffness>0</spring_stiffness>
          <damping>0.0001</damping>
          <friction>0</friction>
        </dynamics>
      </axis>
      <physics>
        <ode>
          <limit>
            <cfm>0</cfm>
            <erp>0.2</erp>
          </limit>
          <suspension>
            <cfm>0</cfm>
            <erp>0.2</erp>
          </suspension>
        </ode>
      </physics>
    </joint>
    <joint name='r1_joint' type='revolute'>
      <parent>body_1</parent>
      <child>rod_1</child>
      <pose frame=''>0 0 0 0 -0 0</pose>
      <axis>
        <xyz>0 0 -1</xyz>
        <use_parent_model_frame>0</use_parent_model_frame>
        <limit>
          <lower>-1e+16</lower>
          <upper>1e+16</upper>
          <effort>-1</effort>
          <velocity>-1</velocity>
        </limit>
        <dynamics>
          <spring_reference>0</spring_reference>
          <spring_stiffness>0</spring_stiffness>
          <damping>0.0001</damping>
          <friction>0</friction>
        </dynamics>
      </axis>
      <physics>
        <ode>
          <limit>
            <cfm>0</cfm>
            <erp>0.2</erp>
          </limit>
          <suspension>
            <cfm>0</cfm>
            <erp>0.2</erp>
          </suspension>
        </ode>
      </physics>
    </joint>
    <joint name='r2_joint' type='revolute'>
      <parent>body_1</parent>
      <child>rod_2</child>
      <pose frame=''>0 0 0 0 -0 0</pose>
      <axis>
        <xyz>0 0 -1</xyz>
        <use_parent_model_frame>0</use_parent_model_frame>
        <limit>
          <lower>-1e+16</lower>
          <upper>1e+16</upper>
          <effort>-1</effort>
          <velocity>-1</velocity>
        </limit>
        <dynamics>
          <spring_reference>0</spring_reference>
          <spring_stiffness>0</spring_stiffness>
          <damping>0.0001</damping>
          <friction>0</friction>
        </dynamics>
      </axis>
      <physics>
        <ode>
          <limit>
            <cfm>0</cfm>
            <erp>0.2</erp>
          </limit>
          <suspension>
            <cfm>0</cfm>
            <erp>0.2</erp>
          </suspension>
        </ode>
      </physics>
    </joint>
    <joint name='r3_joint' type='revolute'>
      <parent>body_2</parent>
      <child>rod_3</child>
      <pose frame=''>0 0 0 0 -0 0</pose>
      <axis>
        <xyz>0 0 1</xyz>
        <use_parent_model_frame>0</use_parent_model_frame>
        <limit>
          <lower>-1e+16</lower>
          <upper>1e+16</upper>
          <effort>-1</effort>
          <velocity>-1</velocity>
        </limit>
        <dynamics>
          <spring_reference>0</spring_reference>
          <spring_stiffness>0</spring_stiffness>
          <damping>0.0001</damping>
          <friction>0</friction>
        </dynamics>
      </axis>
      <physics>
        <ode>
          <limit>
            <cfm>0</cfm>
            <erp>0.2</erp>
          </limit>
          <suspension>
            <cfm>0</cfm>
            <erp>0.2</erp>
          </suspension>
        </ode>
      </physics>
    </joint>
    <joint name='r4_joint' type='revolute'>
      <parent>body_2</parent>
      <child>rod_4</child>
      <pose frame=''>0 0 0 0 -0 0</pose>
      <axis>
        <xyz>0 0 1</xyz>
        <use_parent_model_frame>0</use_parent_model_frame>
        <limit>
          <lower>-1e+16</lower>
          <upper>1e+16</upper>
          <effort>-1</effort>
          <velocity>-1</velocity>
        </limit>
        <dynamics>
          <spring_reference>0</spring_reference>
          <spring_stiffness>0</spring_stiffness>
          <damping>0.0001</damping>
          <friction>0</friction>
        </dynamics>
      </axis>
      <physics>
        <ode>
          <limit>
            <cfm>0</cfm>
            <erp>0.2</erp>
          </limit>
          <suspension>
            <cfm>0</cfm>
            <erp>0.2</erp>
          </suspension>
        </ode>
      </physics>
    </joint>
    <static>0</static>
    <allow_auto_disable>1</allow_auto_disable>
    <plugin name='blade_1' filename='libLiftDragPlugin.so'>
      <a0>0.1</a0>
      <cla>0.100</cla>
      <cda>0.01</cda>
      <cma>0.00</cma>
      <alpha_stall>0.2</alpha_stall>
      <cla_stall>-0.2</cla_stall>
      <cda_stall>1.0</cda_stall>
      <cma_stall>0.0</cma_stall>
      <cp>0.0 0.5 0</cp>
      <area>0.2</area>
      <air_density>1.2041</air_density>
      <forward>1 0 0</forward>
      <upward>0 0 1</upward>
      <link_name>drone500::blade_1</link_name>
    </plugin>
    <plugin name='blade_2' filename='libLiftDragPlugin.so'>
      <a0>0.1</a0>
      <cla>0.100</cla>
      <cda>0.01</cda>
      <cma>0.00</cma>
      <alpha_stall>0.2</alpha_stall>
      <cla_stall>-0.2</cla_stall>
      <cda_stall>1.0</cda_stall>
      <cma_stall>0.0</cma_stall>
      <cp>0.0 0.5 0</cp>
      <area>0.2</area>
      <air_density>1.2041</air_density>
      <forward>1 0 0</forward>
      <upward>0 0 1</upward>
      <link_name>drone500::blade_2</link_name>
    </plugin>
    <plugin name='blade_3' filename='libLiftDragPlugin.so'>
      <a0>0.1</a0>
      <cla>0.100</cla>
      <cda>0.01</cda>
      <cma>0.00</cma>
      <alpha_stall>0.2</alpha_stall>
      <cla_stall>-0.2</cla_stall>
      <cda_stall>1.0</cda_stall>
      <cma_stall>0.0</cma_stall>
      <cp>0.0 0.5 0</cp>
      <area>0.2</area>
      <air_density>1.2041</air_density>
      <forward>1 0 0</forward>
      <upward>0 0 1</upward>
      <link_name>drone500::blade_3</link_name>
    </plugin>
    <plugin name='blade_4' filename='libLiftDragPlugin.so'>
      <a0>0.1</a0>
      <cla>0.100</cla>
      <cda>0.01</cda>
      <cma>0.00</cma>
      <alpha_stall>0.2</alpha_stall>
      <cla_stall>-0.2</cla_stall>
      <cda_stall>1.0</cda_stall>
      <cma_stall>0.0</cma_stall>
      <cp>0.0 0.5 0</cp>
      <area>0.2</area>
      <air_density>1.2041</air_density>
      <forward>1 0 0</forward>
      <upward>0 0 1</upward>
      <link_name>drone500::blade_4</link_name>
    </plugin>
    <plugin name='blade_5' filename='libLiftDragPlugin.so'>
      <a0>0.1</a0>
      <cla>0.100</cla>
      <cda>0.01</cda>
      <cma>0.00</cma>
      <alpha_stall>0.2</alpha_stall>
      <cla_stall>-0.2</cla_stall>
      <cda_stall>1.0</cda_stall>
      <cma_stall>0.0</cma_stall>
      <cp>0.0 0.5 0</cp>
      <area>0.2</area>
      <air_density>1.2041</air_density>
      <forward>-1 0 0</forward>
      <upward>0 0 1</upward>
      <link_name>drone500::blade_5</link_name>
    </plugin>
    <plugin name='blade_6' filename='libLiftDragPlugin.so'>
      <a0>0.1</a0>
      <cla>0.100</cla>
      <cda>0.01</cda>
      <cma>0.00</cma>
      <alpha_stall>0.2</alpha_stall>
      <cla_stall>-0.2</cla_stall>
      <cda_stall>1.0</cda_stall>
      <cma_stall>0.0</cma_stall>
      <cp>0.0 0.5 0</cp>
      <area>0.2</area>
      <air_density>1.2041</air_density>
      <forward>-1 0 0</forward>
      <upward>0 0 1</upward>
      <link_name>drone500::blade_6</link_name>
    </plugin>
    <plugin name='blade_7' filename='libLiftDragPlugin.so'>
      <a0>0.1</a0>
      <cla>0.100</cla>
      <cda>0.01</cda>
      <cma>0.00</cma>
      <alpha_stall>0.2</alpha_stall>
      <cla_stall>-0.2</cla_stall>
      <cda_stall>1.0</cda_stall>
      <cma_stall>0.0</cma_stall>
      <cp>0.0 0.5 0</cp>
      <area>0.2</area>
      <air_density>1.2041</air_density>
      <forward>-1 0 0</forward>
      <upward>0 0 1</upward>
      <link_name>drone500::blade_7</link_name>
    </plugin>
    <plugin name='blade_8' filename='libLiftDragPlugin.so'>
      <a0>0.1</a0>
      <cla>0.100</cla>
      <cda>0.01</cda>
      <cma>0.00</cma>
      <alpha_stall>0.2</alpha_stall>
      <cla_stall>-0.2</cla_stall>
      <cda_stall>1.0</cda_stall>
      <cma_stall>0.0</cma_stall>
      <cp>0.0 0.5 0</cp>
      <area>0.2</area>
      <air_density>1.2041</air_density>
      <forward>-1 0 0</forward>
      <upward>0 0 1</upward>
      <link_name>drone500::blade_8</link_name>
    </plugin>
  </model>
</sdf>
